2020-02-08 09:31:47,022 fox log.py debug
2020-02-08 09:31:47,022 fox log.py 提示
2020-02-08 09:35:24,344 fox log.py debug
2020-02-08 09:35:24,344 fox log.py 提示
2020-02-08 09:35:58,617 fox log.py debug
2020-02-08 09:35:58,617 fox log.py 提示
2020-02-08 09:37:59,783 - log.py:[28] - [WARNING] - debug
2020-02-08 09:37:59,783 - log.py:[29] - [INFO] - 提示
2020-02-08 09:41:10,712 fox log.py debug
2020-02-08 09:41:10,712 fox log.py 提示
2020-02-08 09:43:14,139 - log.py:[32] - [WARNING] - debug
2020-02-08 09:43:14,139 - log.py:[33] - [INFO] - 提示
2020-02-08 09:45:57,814 - log.py:[31] - [WARNING] - debug
2020-02-08 09:45:57,814 - log.py:[29] - [INFO] - 提示
2020-02-08 09:46:09,296 - log.py:[31] - [WARNING] - debug
2020-02-08 09:46:09,296 - log.py:[33] - [ERROR] - 提示
2020-02-08 09:58:41,300 - log.py:[31] - [WARNING] - debug
2020-02-08 09:58:41,300 - log.py:[33] - [ERROR] - 提示
2020-02-08 10:00:10,189 - log.py:[31] - [WARNING] - debug
2020-02-08 10:00:10,189 - log.py:[33] - [ERROR] - 提示
2020-02-08 10:00:54,151 - log.py:[31] - [WARNING] - debug
2020-02-08 10:00:54,151 - log.py:[33] - [ERROR] - 提示
2020-02-08 10:20:49,333 -fox- log.py:[31] - [WARNING] - debug
2020-02-08 10:20:49,333 -fox- log.py:[33] - [ERROR] - 提示
2020-02-08 10:29:22,662 -Retail.Test_case.models.Doconfini- log.py:[29] - [INFO] - read excel value [D:\JekinsProject] successed!
2020-02-08 10:30:56,764 -Retail.Test_case.models.Doconfini- log.py:[29] - [INFO] - read excel value [D:\JekinsProject] successed!
2020-02-08 10:32:08,790 -Retail.Test_case.models.Doconfini- log.py:[29] - [INFO] - read excel value [D:\JekinsProject] successed!
2020-02-08 10:33:06,775 -Retail.Test_case.models.Doconfini- log.py:[29] - [INFO] - read excel value [D:\JekinsProject] successed!
2020-02-08 10:33:28,163 -Retail.Test_case.models.Doconfini- log.py:[29] - [INFO] - read excel value [D:\JekinsProject] successed!
2020-02-08 11:12:33,581 -Retail.Test_case.models.Doconfini- log.py:[29] - [INFO] - read excel value [D:\JekinsProject] successed!
2020-02-08 11:24:34,240 -fox- log.py:[36] - [WARNING] - debug
2020-02-08 11:24:34,240 -fox- log.py:[38] - [ERROR] - 提示
2020-02-08 11:25:12,522 -fox- log.py:[34] - [WARNING] - debug
2020-02-08 11:25:12,522 -fox- log.py:[36] - [ERROR] - 提示
2020-02-08 11:25:38,075 -Retail.Test_case.models.Doconfini- log.py:[32] - [INFO] - read excel value [D:\JekinsProject] successed!
2020-02-08 11:41:46,232 -Retail.Test_case.models.Doconfini- log.py:[32] - [INFO] - read excel value [D:\JekinsProject] successed!
2020-02-08 11:42:05,389 -Retail.Test_case.models.Doconfini- log.py:[32] - [INFO] - read excel value [D:\JekinsProject] successed!
2020-02-08 11:42:05,389 -__main__- log.py:[32] - [INFO] - read excel value [D:\JekinsProject] successed!
2020-02-08 11:43:31,767 -Retail.Test_case.models.Doconfini- log.py:[32] - [INFO] - read excel value [D:\JekinsProject] successed!
2020-02-08 11:43:31,767 -__main__- log.py:[32] - [INFO] - read excel value [D:\JekinsProject] successed!
2020-02-08 11:43:31,767 -__main__- log.py:[32] - [INFO] - write section tesesection with value hello word successed!
2020-02-08 13:58:18,324 -Retail.Test_case.models.Doconfini- log.py:[32] - [INFO] - read excel value [D:\JekinsProject] successed!
2020-02-08 13:58:48,824 -Retail.Test_case.models.Doconfini- log.py:[32] - [INFO] - read excel value [D:\JekinsProject] successed!
2020-02-08 13:58:48,825 -__main__- log.py:[40] - [ERROR] - init class ReadExcel fail
Traceback (most recent call last):
  File "D:/JekinsProject/Retail/Test_case/models/Doexcel.py", line 18, in __init__
    self.workbook = xlrd.open_workbook(self.dataFile)
  File "D:\JekinsProject\venv\lib\site-packages\xlrd\__init__.py", line 111, in open_workbook
    with open(filename, "rb") as f:
FileNotFoundError: [Errno 2] No such file or directory: 'D:\\JekinsProject\\Retail\\report\\TestData\\elementData.xlsx'
2020-02-08 13:59:57,521 -Retail.Test_case.models.Doconfini- log.py:[32] - [INFO] - read excel value [D:\JekinsProject] successed!
2020-02-08 13:59:57,521 -__main__- log.py:[40] - [ERROR] - init class ReadExcel fail
Traceback (most recent call last):
  File "D:/JekinsProject/Retail/Test_case/models/Doexcel.py", line 18, in __init__
    self.workbook = xlrd.open_workbook(self.dataFile)
  File "D:\JekinsProject\venv\lib\site-packages\xlrd\__init__.py", line 111, in open_workbook
    with open(filename, "rb") as f:
FileNotFoundError: [Errno 2] No such file or directory: 'D:\\JekinsProject\\Retail\\report\\TestData\\elementData.xlsx'
2020-02-08 14:00:09,818 -Retail.Test_case.models.Doconfini- log.py:[32] - [INFO] - read excel value [D:\JekinsProject] successed!
2020-02-08 14:00:09,818 -__main__- log.py:[40] - [ERROR] - init class ReadExcel fail
Traceback (most recent call last):
  File "D:/JekinsProject/Retail/Test_case/models/Doexcel.py", line 18, in __init__
    self.workbook = xlrd.open_workbook(self.dataFile)
  File "D:\JekinsProject\venv\lib\site-packages\xlrd\__init__.py", line 111, in open_workbook
    with open(filename, "rb") as f:
FileNotFoundError: [Errno 2] No such file or directory: 'D:\\JekinsProject\\Retail\\report\\TestData\\elementData.xls'
2020-02-08 14:00:51,778 -Retail.Test_case.models.Doconfini- log.py:[32] - [INFO] - read excel value [D:\JekinsProject] successed!
2020-02-08 14:00:51,779 -__main__- log.py:[40] - [ERROR] - init class ReadExcel fail
Traceback (most recent call last):
  File "D:/JekinsProject/Retail/Test_case/models/Doexcel.py", line 18, in __init__
    self.workbook = xlrd.open_workbook(self.dataFile)
  File "D:\JekinsProject\venv\lib\site-packages\xlrd\__init__.py", line 111, in open_workbook
    with open(filename, "rb") as f:
FileNotFoundError: [Errno 2] No such file or directory: 'D:\\JekinsProject\\Retail\\TestData\\elementData.xls'
2020-02-08 14:01:43,942 -Retail.Test_case.models.Doconfini- log.py:[32] - [INFO] - read excel value [D:\JekinsProject] successed!
2020-02-08 14:01:43,942 -__main__- log.py:[40] - [ERROR] - init class ReadExcel fail
Traceback (most recent call last):
  File "D:/JekinsProject/Retail/Test_case/models/Doexcel.py", line 18, in __init__
    self.workbook = xlrd.open_workbook(self.dataFile)
  File "D:\JekinsProject\venv\lib\site-packages\xlrd\__init__.py", line 111, in open_workbook
    with open(filename, "rb") as f:
FileNotFoundError: [Errno 2] No such file or directory: 'D:\\JekinsProject\\Retail\\TestData\\elementData.xls'
2020-02-08 14:02:40,617 -Retail.Test_case.models.Doconfini- log.py:[32] - [INFO] - read excel value [D:\JekinsProject] successed!
2020-02-08 14:02:40,633 -__main__- log.py:[40] - [ERROR] - init class ReadExcel fail
Traceback (most recent call last):
  File "D:/JekinsProject/Retail/Test_case/models/Doexcel.py", line 18, in __init__
    self.workbook = xlrd.open_workbook(self.dataFile)
  File "D:\JekinsProject\venv\lib\site-packages\xlrd\__init__.py", line 111, in open_workbook
    with open(filename, "rb") as f:
FileNotFoundError: [Errno 2] No such file or directory: 'D:\\JekinsProject\\Retail\\Data\\TestData\\elementData.xls'
2020-02-08 14:03:03,806 -Retail.Test_case.models.Doconfini- log.py:[32] - [INFO] - read excel value [D:\JekinsProject] successed!
2020-02-08 14:03:03,822 -__main__- log.py:[40] - [ERROR] - init class ReadExcel fail
Traceback (most recent call last):
  File "D:\JekinsProject\venv\lib\site-packages\xlrd\book.py", line 474, in sheet_by_name
    sheetx = self._sheet_names.index(sheet_name)
ValueError: 'elementsInfo' is not in list

During handling of the above exception, another exception occurred:

Traceback (most recent call last):
  File "D:/JekinsProject/Retail/Test_case/models/Doexcel.py", line 19, in __init__
    self.sheetName = self.workbook.sheet_by_name(sheetName)
  File "D:\JekinsProject\venv\lib\site-packages\xlrd\book.py", line 476, in sheet_by_name
    raise XLRDError('No sheet named <%r>' % sheet_name)
xlrd.biffh.XLRDError: No sheet named <'elementsInfo'>
2020-02-08 14:03:37,025 -Retail.Test_case.models.Doconfini- log.py:[32] - [INFO] - read excel value [D:\JekinsProject] successed!
2020-02-08 14:03:37,031 -__main__- log.py:[32] - [INFO] - initing class ReadExcel
2020-02-08 14:03:37,031 -__main__- log.py:[40] - [ERROR] - read value excel file fail
Traceback (most recent call last):
  File "D:/JekinsProject/Retail/Test_case/models/Doexcel.py", line 29, in readExcel
    value = self.sheetName.cell(rownum,colnum).value
  File "D:\JekinsProject\venv\lib\site-packages\xlrd\sheet.py", line 412, in cell
    self._cell_types[rowx][colx],
IndexError: array index out of range
2020-02-08 14:07:31,207 -Retail.Test_case.models.Doconfini- log.py:[32] - [INFO] - read excel value [D:\JekinsProject] successed!
2020-02-08 14:07:31,212 -__main__- log.py:[32] - [INFO] - initing class ReadExcel
2020-02-08 14:07:31,212 -__main__- log.py:[32] - [INFO] - reading value [id] from excel file [D:\JekinsProject\Retail\Data\TestData\elementData.xlsx] completed
2020-02-08 14:58:35,886 -Retail.Test_case.models.Doconfini- log.py:[32] - [INFO] - read excel value [D:\JekinsProject] successed!
2020-02-08 14:58:35,887 -__main__- log.py:[32] - [INFO] - open file [Email_receiver.txt] successed!
2020-02-08 14:58:35,887 -__main__- log.py:[32] - [INFO] - reading [Email_receiver.txt] and got receiver value is [[['187396693@qq.com', 'gaoyuan19840914@163.com']]]
2020-02-08 14:58:35,887 -__main__- log.py:[32] - [INFO] - reading [Email_receiver.txt] and got receiver value is [[['187396693@qq.com', 'gaoyuan19840914@163.com'], ['123@123.com', 'test@163.com']]]
2020-02-08 14:58:35,888 -__main__- log.py:[40] - [ERROR] - open or read file [2018-09-21 17_44_04.html] failed,No such file or directory: D:\JekinsProject\Retail\report\TestReport
Traceback (most recent call last):
  File "D:/JekinsProject/Retail/Test_case/models/Sendmail.py", line 35, in sendEmail
    f = open(os.path.join(Conf.reportPath,filename),'rb')
FileNotFoundError: [Errno 2] No such file or directory: 'D:\\JekinsProject\\Retail\\report\\TestReport\\2018-09-21 17_44_04.html'
2020-02-08 14:58:35,903 -__main__- log.py:[40] - [ERROR] - connect [<smtplib.SMTP object at 0x0000000002D58908>] server failed or username and password incorrect!
Traceback (most recent call last):
  File "D:/JekinsProject/Retail/Test_case/models/Sendmail.py", line 50, in sendEmail
    smtp.connect(self._server)
AttributeError: 'SendMail' object has no attribute '_server'
2020-02-08 14:59:12,766 -Retail.Test_case.models.Doconfini- log.py:[32] - [INFO] - read excel value [D:\JekinsProject] successed!
2020-02-08 14:59:12,766 -__main__- log.py:[32] - [INFO] - open file [Email_receiver.txt] successed!
2020-02-08 14:59:12,766 -__main__- log.py:[32] - [INFO] - reading [Email_receiver.txt] and got receiver value is [[['187396693@qq.com', 'gaoyuan19840914@163.com']]]
2020-02-08 14:59:12,766 -__main__- log.py:[32] - [INFO] - reading [Email_receiver.txt] and got receiver value is [[['187396693@qq.com', 'gaoyuan19840914@163.com'], ['123@123.com', 'test@163.com']]]
2020-02-08 14:59:12,766 -__main__- log.py:[40] - [ERROR] - open or read file [2018-09-21 17_44_04.html] failed,No such file or directory: D:\JekinsProject\Retail\report\TestReport
Traceback (most recent call last):
  File "D:/JekinsProject/Retail/Test_case/models/Sendmail.py", line 35, in sendEmail
    f = open(os.path.join(Conf.reportPath,filename),'rb')
FileNotFoundError: [Errno 2] No such file or directory: 'D:\\JekinsProject\\Retail\\report\\TestReport\\2018-09-21 17_44_04.html'
2020-02-08 14:59:13,063 -__main__- log.py:[40] - [ERROR] - connect [<smtplib.SMTP object at 0x0000000002D49940>] server failed or username and password incorrect!
Traceback (most recent call last):
  File "D:/JekinsProject/Retail/Test_case/models/Sendmail.py", line 51, in sendEmail
    smtp.login(self._fromuser,self._frompassword)
  File "D:\Python37\install\lib\smtplib.py", line 730, in login
    raise last_exception
  File "D:\Python37\install\lib\smtplib.py", line 721, in login
    initial_response_ok=initial_response_ok)
  File "D:\Python37\install\lib\smtplib.py", line 642, in auth
    raise SMTPAuthenticationError(code, resp)
smtplib.SMTPAuthenticationError: (535, b'Error: authentication failed')
